Workbook

Sheet Case Introduction
B1: Jarvis consulting Corp.

Sheet P&L
B5: Particulars | C5: FY 19 | D5: FY 20 | E5: FY 21 | F5: FY 22 | G5: FY 23
B6: Net sales | C6: 82675 | D6: 90791 | E6: 100472 | F6: 121641 | G6: 146767
B7: Cost of sales | C7: 53867 | D7: 60732 | E7: 65413 | F7: 81998 | G7: 102353
B8: Gross profit | C8: =C6-C7 -> 28808 | D8: =D6-D7 -> 30059 | E8: =E6-E7 -> 35059 | F8: =F6-F7 -> 39643 | G8: =G6-G7 -> 44414
B10: Selling, general and administrative expenses | C10: 9928 | D10: 10685 | E10: 10437 | F10: 11628 | G10: 13509
B11: Other (income) expense, net | C11: -2161 | D11: -2803 | E11: -2201 | F11: -2295 | G11: -2701
B12: EBIT | C12: =C8-C10-C11 -> 21041 | D12: =D8-D10-D11 -> 22177 | E12: =E8-E10-E11 -> 26823 | F12: =F8-F10-F11 -> 30310 | G12: =G8-G10-G11 -> 33606
B13: Other finance charges | C13: 0 | D13: 0 | E13: 0 | F13: 0 | G13: 0
B14: Interest expense, net | C14: 0 | D14: -170 | E14: -195 | F14: -200 | G14: 284
B16: EBT | C16: =C12-C14-C13 -> 21041 | D16: =D12-D14-D13 -> 22347 | E16: =E12-E14-E13 -> 27018 | F16: =F12-F14-F13 -> 30510 | G16: =G12-G14-G13 -> 33322
B17: Provision for income taxes | C17: 5631 | D17: 5368 | E17: 7205 | F17: 7964 | G17: 9214
B18: Net income | C18: =C16-C17 -> 15410 | D18: =D16-D17 -> 16979 | E18: =E16-E17 -> 19813 | F18: =F16-F17 -> 22546 | G18: =G16-G17 -> 24108
B19: Earnings per common share, basic | C19: =C18/C22 -> 35.448674 | D19: =D18/D22 -> 39.877827 | E19: =E18/E22 -> 46.702155 | F19: =F18/F22 -> 53.559211 | G19: =G18/G22 -> 57.662255
B20: Earnings per common share, diluted | C20: =C18/C23 -> 35.397451 | D20: =D18/D23 -> 39.808736 | E20: =E18/E23 -> 46.61079 | F20: =F18/F23 -> 53.445219 | G20: =G18/G23 -> 57.568167
B22: Basic Weighted Average Shares | C22: 434.71302 | D22: 425.77545 | E22: 424.24167 | F22: 420.95467 | G22: 418.08979
B23: Diluted Weighted Average Shares | C23: 435.34208 | D23: 426.51442 | E23: 425.07325 | F23: 421.85251 | G23: 418.77311

Sheet Balance Sheet
A1: ='P&L'!A1 -> 0
B5: Particulars | C5: ='P&L'!C5 -> FY 19 | D5: ='P&L'!D5 -> FY 20 | E5: ='P&L'!E5 -> FY 21 | F5: ='P&L'!F5 -> FY 22 | G5: ='P&L'!G5 -> FY 23
B6: Assets
B7: Current Assets
B8: Cash and cash equivalents | C8: 19568 | D8: 18649 | E8: 24714 | F8: 17472 | G8: 12173
B9: Receivables | C9: 14827 | D9: 18487 | E9: 19294 | F9: 22698 | G9: 25424
B10: Inventories | C10: 0 | D10: 0 | E10: 0 | F10: 0 | G10: 0
B11: Other current assets | C11: 18483 | D11: 17440 | E11: 16725 | F11: 27015 | G11: 33284
B12: Total current assets | C12: =SUM(C8:C11) -> 52878 | D12: =SUM(D8:D11) -> 54576 | E12: =SUM(E8:E11) -> 60733 | F12: =SUM(F8:F11) -> 67185 | G12: =SUM(G8:G11) -> 70881
B14: Property, plant and equipment, net | C14: 11479 | D14: 12435 | E14: 12560 | F14: 13075 | G14: 13346 | J14: =(E8-D8)/D8 -> 0.32521851 | K14: =(F8-E8)/E8 -> -0.29303229
B15: ROU assets | C15: 0 | D15: 4168 | E15: 4794 | F15: 4823 | G15: 6882
B16: Goodwill | C16: 3540 | D16: 5286 | E16: 6079 | F16: 6195 | G16: 7248
B17: Other intangible assets, net | C17: 691 | D17: 1900 | E17: 2072 | F17: 1707 | G17: 1749
B18: Deferred tax assets | C18: 7692 | D18: 7128 | E18: 6909 | F18: 7310 | G18: 7698
B19: Other assets | C19: 8458 | D19: 7275 | E19: 15239 | F19: 17590 | G19: 18012
B20: Total assets | C20: =SUM(C12:C19) -> 84738 | D20: =SUM(D12:D19) -> 92768 | E20: =SUM(E12:E19) -> 108386 | F20: =SUM(F12:F19) -> 117885 | G20: =SUM(G12:G19) -> 125816
B22: Liabilities and Shareholders' Equity
B23: Current Liabilities
B24: Loans payable | C24: 10452 | D24: 10481 | E24: 11390 | F24: 15837 | G24: 18558
B25: Lease liabilities | C25: 0 | D25: 619 | E25: 738 | F25: 872 | G25: 1242
B26: Trade payable | C26: 1655 | D26: 2852 | E26: 2645 | F26: 4134 | G26: 3865
B27: Income tax liabilities | C27: 1567 | D27: 1490 | E27: 2146 | F27: 2607 | G27: 3384
B28: Other accruals | C28: 4964 | D28: 5414 | E28: 6946 | F28: 10153 | G28: 12137
B29: Total current liabilities | C29: =SUM(C24:C28) -> 18638 | D29: =SUM(D24:D28) -> 20856 | E29: =SUM(E24:E28) -> 23865 | F29: =SUM(F24:F28) -> 33603 | G29: =SUM(G24:G28) -> 39186
B31: Long-term debt | C31: 147 | D31: 4821 | E31: 6101 | F31: 6939 | G31: 9115
B32: Deferred income taxes | C32: 672 | D32: 968 | E32: 875 | F32: 1156 | G32: 1220
B33: Other liabilities | C33: 275 | D33: 279 | E33: 763 | F33: 451 | G33: 500
B34: Total liabilities | C34: =SUM(C29:C33) -> 19732 | D34: =SUM(D29:D33) -> 26924 | E34: =SUM(E29:E33) -> 31604 | F34: =SUM(F29:F33) -> 42149 | G34: =SUM(G29:G33) -> 50021
B35: Shareholders' Equity
B36: Equity share capital | C36: 2170 | D36: 2122 | E36: 2124 | F36: 2098 | G36: 2069
B37: Reserves and surplus | C37: 62836 | D37: 63722 | E37: 74658 | F37: 73638 | G37: 73726
B38: Total shareholders' equity | C38: =SUM(C36:C37) -> 65006 | D38: =SUM(D36:D37) -> 65844 | E38: =SUM(E36:E37) -> 76782 | F38: =SUM(F36:F37) -> 75736 | G38: =SUM(G36:G37) -> 75795
B39: Total liabilities and shareholders' equity | C39: =C38+C34 -> 84738 | D39: =D38+D34 -> 92768 | E39: =E38+E34 -> 108386 | F39: =F38+F34 -> 117885 | G39: =G38+G34 -> 125816
B42: Total Check | C42: =C39-C20 -> 0 | D42: =D39-D20 -> 0 | E42: =E39-E20 -> 0 | F42: =F39-F20 -> 0 | G42: =G39-G20 -> 0

Sheet Cash Flow
A1: ='P&L'!A1 -> 0
B5: Particulars | C5: FY 19 | D5: FY 20 | E5: FY 21 | F5: FY 22 | G5: FY 23
B6: Operating Activities
B7: Net Profit | C7: 15410 | D7: 16639 | E7: 19423 | F7: 22146 | G7: 24108
B8: Adjustments to reconcile net profit to cash generated from operations:
B9: Income tax | C9: 5631 | D9: 5368 | E9: 7205 | F9: 7964 | G9: 9214
B10: Depreciation and amortization | C10: 2011 | D10: 2893 | E10: 3267 | F10: 3476 | G10: 4225
B11: Interest and dividend income | C11: -2052 | D11: -1613 | E11: -1615 | F11: -1645 | G11: -1817
B12: Finance cost | C12: 0 | D12: 170 | E12: 195 | F12: 200 | G12: 284
B13: Loss on impairment Financial instruments | C13: 239 | D13: 161 | E13: 190 | F13: 170 | G13: 283
B14: Reduction in fair value disposal group held for sale | C14: 270 | D14: 0 | E14: 0 | F14: 0 | G14: 0
B15: Impairment loss on reclassification from "Held for Sale" | C15: 451 | D15: 0 | E15: 0 | F15: 0 | G15: 0
B16: Exchange differences on translation | C16: 66 | D16: 184 | E16: -62 | F16: 119 | G16: 161
B17: Stock compensation expense | C17: 202 | D17: 249 | E17: 333 | F17: 415 | G17: 519
B18: Other adjustments | C18: -102 | D18: -131 | E18: -91 | F18: 76 | G18: 628
B19: Cash effects of changes in:
B20: Trade receivables and Unbilled revenue | C20: -2881 | D20: -3861 | E20: -1835 | F20: -7937 | G20: -7076
B21: Loans, other financial assets and other assets | C21: -700 | D21: 76 | E21: -534 | F21: -1914 | G21: -3108
B22: Trade payables | C22: 916 | D22: -373 | E22: -245 | F22: 1489 | G22: -279
B23: Other financial liabilities, other liabilities and provisions | C23: 2212 | D23: 1791 | E23: 3382 | F23: 6938 | G23: 4119
B24: Cash generated from operations | C24: 21673 | D24: 21553 | E24: 29613 | F24: 31497 | G24: 31261
B25: Income taxes paid | C25: -6832 | D25: -4550 | E25: -6389 | F25: -7612 | G25: -8794
B26: Net cash provided by operations | C26: 14841 | D26: 17003 | E26: 23224 | F26: 23885 | G26: 22467
B28: Investing Activities
B29: Expenditure on PPE and intangibles | C29: -2445 | D29: -3307 | E29: -2107 | F29: -2161 | G29: -2579
B30: Corporate Deposits placed | C30: -24 | D30: -108 | E30: -725 | F30: -906 | G30: -996
B31: Loans to employees | C31: 14 | D31: 0 | E31: 0 | F31: 0 | G31: 0
B32: Corporate Depsits redeemed | C32: 0 | D32: 0 | E32: 518 | F32: 753 | G32: 762
B33: Interest and Dividend received | C33: 1557 | D33: 1929 | E33: 1418 | F33: 1898 | G33: 1525
B34: Business acquisition, net of cash | C34: -550 | D34: -1860 | E34: -1221 | F34: 0 | G34: -910
B35: Contingent consideration on business acquisition | C35: -18 | D35: -6 | E35: -158 | F35: -53 | G35: -60
B36: Advance consideration on business acquisition | C36: -206 | D36: 0 | E36: 0 | F36: 0 | G36: 0
B37: Escrow deposits for buyback | C37: -257 | D37: 0 | E37: 0 | F37: -420 | G37: -483
B38: Redemption of escrow deposits for buyback | C38: 0 | D38: 257 | E38: 0 | F38: 420 | G38: 483
B39: Other receipts | C39: 0 | D39: 46 | E39: 49 | F39: 67 | G39: 71
B40: Other payments | C40: 0 | D40: 0 | E40: -45 | F40: -22 | G40: 0
... B43: Net cash used in investing activities | C43: -575 | D43: -239 | E43: -7456 | F43: -6416 | G43: -1209
B45: Financing Activities
B46: Revolver
B47: Payments of lease liabilities | C47: 0 | D47: -571 | E47: -698 | F47: -915 | G47: -1231
...

Sheet Relative valuation
D2: Market data | I2: Financials | M2: Valuation
B3: S.No. | C3: Company | D3: EV Rs.Cr. | E3: CMP Rs. | F3: Shares outstanding | G3: Equity value | I3: Revenue Rs. Cr. | J3: EBITDA Rs.Cr. | K3: EBIT Rs.Cr. | M3: Price / Revenue | N3: EV / EBITDA | O3: EV / EBIT
B4: 1 | C4: Trance consultants | D4: 1169199 | E4: 3204.5 | F4: 365.91 | G4: 1172558.6 | I4: 225458 | J4: 62678 | K4: 57656 | M4: =G4/I4 -> 5.200785 | N4: =D4/J4 -> 18.654057 | O4: =D4/K4 -> 20.278878
B5: 2 | C5: Haway consulting | D5: 298958.54 | E5: 1138.3 | F5: 271.37 | G5: 308900.47 | I5: 101456 | J5: 23986 | K5: 19841 | M5: =G5/I5 -> 3.0446743 | N5: =D5/J5 -> 12.463876 | O5: =D5/K5 -> 15.067715
B6: 3 | C6: Winners consulting | D6: 218473.79 | E6: 382.95 | F6: 548.88 | G6: 210193.6 | I6: 90487.6 | J6: 19113.6 | K6: 15773.4 | M6: =G6/I6 -> 2.3228994 | N6: =D6/J6 -> 11.430279 | O6: =D6/K6 -> 13.850773
B7: 4 | C7: Leap consulting | D7: 146433.52 | E7: 4996 | F7: 29.59 | G7: 147831.64 | I7: 33183 | J7: 6664.6 | K7: 5941.9 | M7: =G7/I7 -> 4.4550414 | N7: =D7/J7 -> 21.971839 | O7: =D7/K7 -> 24.644225
B9: High | M9: =MAX(M4:M7) -> 5.200785 | N9: =MAX(N4:N7) -> 21.971839 | O9: =MAX(O4:O7) -> 24.644225
B10: 75th percentile | M10: =_xlfn.PERCENTILE.INC(M4:M7,0.75) -> 4.6414773 | N10: =_xlfn.PERCENTILE.INC(N4:N7,0.75) -> 19.483503 | O10: =_xlfn.PERCENTILE.INC(O4:O7,0.75) -> 21.370215
B11: Average | M11: =AVERAGE(M4:M7) -> 3.75585 | N11: =AVERAGE(N4:N7) -> 16.130013 | O11: =AVERAGE(O4:O7) -> 18.460398
B12: Median | M12: =_xlfn.PERCENTILE.INC(M4:M7,0.5) -> 3.7498578 | N12: =_xlfn.PERCENTILE.INC(N4:N7,0.5) -> 15.558967 | O12: =_xlfn.PERCENTILE.INC(O4:O7,0.5) -> 17.673297
B13: 25th percentile | M13: =_xlfn.PERCENTILE.INC(M4:M7,0.25) -> 2.8642306 | N13: =_xlfn.PERCENTILE.INC(N4:N7,0.25) -> 12.205477 | O13: =_xlfn.PERCENTILE.INC(O4:O7,0.25) -> 14.76348
B14: Low | M14: =MIN(M4:M7) -> 2.3228994 | N14: =MIN(N4:N7) -> 11.430279 | O14: =MIN(O4:O7) -> 13.850773
B16: Valuation of Jarvis consulting corporation
I18: Financials | M18: Valuation
B19: S.No. | C19: Company | I19: Revenue Rs. Cr. | J19: EBITDA Rs.Cr. | K19: EBIT Rs.Cr. | M19: Price / Revenue | N19: EV / EBITDA | O19: EV / EBIT
B20: 1 | C20: Jarvis consulting | I20: 146767 | J20: 37831 | K20: 33606 | M20: =M12 -> 3.7498578 | N20: =N12 -> 15.558967 | O20: =O12 -> 17.673297
B22: Enterprise value (Debt & Equity valuation) | M22: =I20*M20 -> 550355.39 | N22: =J20*N20 -> 588611.27 | O22: =K20*O20 -> 593928.81
B23: Less - Gross debt of Jarvis consulting | N23: =SUM('Balance Sheet'!G24,'Balance Sheet'!G25,'Balance Sheet'!G31) -> 28915 | O23: =N23 -> 28915
B24: Add - Cash of Jarvis consulting | N24: ='Balance Sheet'!G8 -> 12173 | O24: =N24 -> 12173
B25: Equity value (Market capitalisation) | M25: =M22 -> 550355.39 | N25: =SUM(N22,N24)-N23 -> 571869.27 | O25: =SUM(O22,O24)-O23 -> 577186.81
B27: Equity value (Market capitalisation) | M27: =M25 -> 550355.39 | N27: =N25 -> 571869.27 | O27: =O25 -> 577186.81
B28: Shares outstanding | O28: 418.08979
B29: Share value | M29: =M27/O$28 -> 1316.3569 | N29: =N27/$O28 -> 1367.8145 | O29: =O27/$O28 -> 1380.5331
B31: Gross Debt Calculation (FY23)
B32: Loans payable | C32: ='Balance Sheet'!G24 -> 18558
B33: Lease liabilities | C33: ='Balance Sheet'!G25 -> 1242
B34: Long-term debt | C34: ='Balance Sheet'!G31 -> 9115
B35: Total Gross Debt | C35: =SUM(C32:C34) -> 28915

Sheet BS Analysis sheet
A1: ='P&L'!A1 -> 0
B5: Particulars | C5: ='Balance Sheet'!C5 -> FY 19 | D5: ='Balance Sheet'!D5 -> FY 20 | E5: ='Balance Sheet'!E5 -> FY 21 | F5: ='Balance Sheet'!F5 -> FY 22 | G5: ='Balance Sheet'!G5 -> FY 23
B6: Assets
B7: Current Assets
B8: Cash and cash equivalents | C8: 19568 | D8: 18649 | E8: 24714 | F8: 17472 | G8: 12173
B9: Receivables | C9: 14827 | D9: 18487 | E9: 19294 | F9: 22698 | G9: 25424
B10: Inventories
B11: Other current assets | C11: 18483 | D11: 17440 | E11: 16725 | F11: 27015 | G11: 33284
B12: Total current assets | C12: =SUM(C8:C11) -> 52878 | D12: =SUM(D8:D11) -> 54576 | E12: =SUM(E8:E11) -> 60733 | F12: =SUM(F8:F11) -> 67185 | G12: =SUM(G8:G11) -> 70881
B14: Property, plant and equipment, net | C14: 11479 | D14: 12435 | E14: 12560 | F14: 13075 | G14: 13346
B15: ROU assets | C15: 0 | D15: 4168 | E15: 4794 | F15: 4823 | G15: 6882
B16: Goodwill, net | C16: 3540 | D16: 5286 | E16: 6079 | F16: 6195 | G16: 7248
B17: Other intangible assets, net | C17: 691 | D17: 1900 | E17: 2072 | F17: 1707 | G17: 1749
B18: Deferred income taxes | C18: 7692 | D18: 7128 | E18: 6909 | F18: 7310 | G18: 7698
B19: Other assets | C19: 8458 | D19: 7275 | E19: 15239 | F19: 17590 | G19: 18012
B20: Total assets | C20: =SUM(C12:C19) -> 84738 | D20: =SUM(D12:D19) -> 92768 | E20: =SUM(E12:E19) -> 108386 | F20: =SUM(F12:F19) -> 117885 | G20: =SUM(G12:G19) -> 125816
B22: Liabilities and Shareholders' Equity
B23: Current Liabilities
B24: Notes and loans payable | C24: 10452 | D24: 10481 | E24: 11390 | F24: 15837 | G24: 18558
B25: Current portion of long-term debt | C25: 0 | D25: 0 | E25: 0 | F25: 0 | G25: 0
B26: Lease Liabilities | C26: 0 | D26: 619 | E26: 738 | F26: 872 | G26: 1242
B27: Accounts payable | C27: 1655 | D27: 2852 | E27: 2645 | F27: 4134 | G27: 3865
B28: Accrued income taxes | C28: 1567 | D28: 1490 | E28: 2146 | F28: 2607 | G28: 3384
B29: Other accruals | C29: 4964 | D29: 5414 | E29: 6946 | F29: 10153 | G29: 12137
B30: Total current liabilities | C30: =SUM(C24:C29) -> 18638 | D30: =SUM(D24:D29) -> 20856 | E30: =SUM(E24:E29) -> 23865 | F30: =SUM(F24:F29) -> 33603 | G30: =SUM(G24:G29) -> 39186
B32: Long-term debt | C32: 147 | D32: 4821 | E32: 6101 | F32: 6939 | G32: 9115
B33: Deferred income taxes | C33: 672 | D33: 968 | E33: 875 | F33: 1156 | G33: 1220
B34: Other liabilities | C34: 275 | D34: 279 | E34: 763 | F34: 451 | G34: 500
B35: Total liabilities | C35: =SUM(C30:C34) -> 19732 | D35: =SUM(D30:D34) -> 26924 | E35: =SUM(E30:E34) -> 31604 | F35: =SUM(F30:F34) -> 42149 | G35: =SUM(G30:G34) -> 50021
B37: Shareholders' Equity
B38: Common stock | C38: 2170 | D38: 2122 | E38: 2124 | F38: 2098 | G38: 2069
B39: Reserves and Surplus | C39: 62836 | D39: 63722 | E39: 74658 | F39: 73638 | G39: 73726
B40: Total shareholders' equity | C40: =SUM(C38:C39) -> 65006 | D40: =SUM(D38:D39) -> 65844 | E40: =SUM(E38:E39) -> 76782 | F40: =SUM(F38:F39) -> 75736 | G40: =SUM(G38:G39) -> 75795
B41: Total liabilities and shareholders' equity | C41: =C40+C35 -> 84738 | D41: =D40+D35 -> 92768 | E41: =E40+E35 -> 108386 | F41: =F40+F35 -> 117885 | G41: =G40+G35 -> 125816
B44: Solvency Ratios
B45: Current ratio | C45: =C12/C30 -> 2.837107 | D45: =D12/D30 -> 2.6168009 | E45: =E12/E30 -> 2.5448565 | F45: =F12/F30 -> 1.9993751 | G45: =G12/G30 -> 1.8088348
B46: Quick ratio | C46: =(C12-C10)/C30 -> 2.837107 | D46: =(D12-D10)/D30 -> 2.6168009 | E46: =(E12-E10)/E30 -> 2.5448565 | F46: =(F12-F10)/F30 -> 1.9993751 | G46: =(G12-G10)/G30 -> 1.8088348
B48: Sales (in Rs.) | C48: 82675 | D48: 90791 | E48: 100472 | F48: 121641 | G48: 146767
B49: COGS (in Rs.) | C49: 53867 | D49: 60732 | E49: 65413 | F49: 81998 | G49: 102353
B51: Turnover Ratios
...

Sheet P&L Analysis sheet
A1: ='P&L'!A1 -> 0
B4: ='P&L'!$B$5 -> Particulars | C4: ='P&L'!C5 -> FY 19 | D4: ='P&L'!D5 -> FY 20 | E4: ='P&L'!E5 -> FY 21 | F4: ='P&L'!F5 -> FY 22 | G4: ='P&L'!G5 -> FY 23
B5: Net sales | C5: =C25/C25 -> 1 | D5: =D25/D25 -> 1 | E5: =E25/E25 -> 1 | F5: =F25/F25 -> 1 | G5: =G25/G25 -> 1
B6: Cost of sales | C6: =C26/C25 -> 0.65155125 | D6: =D26/D25 -> 0.66892093 | E6: =E26/E25 -> 0.65105701 | F6: =F26/F25 -> 0.67409837 | G6: =G26/G25 -> 0.69738429
B7: Gross profit Margin | C7: =C27/C25 -> 0.34844875 | D7: =D27/D25 -> 0.33107907 | E7: =E27/E25 -> 0.34894299 | F7: =F27/F25 -> 0.32590163 | G7: =G27/G25 -> 0.30261571
B9: Selling, general and administrative expenses | C9: =C29/C25 -> 0.12008467 | D9: =D29/D25 -> 0.11768788 | E9: =E29/E25 -> 0.10387969 | F9: =F29/F25 -> 0.095592769 | G9: =G29/G25 -> 0.092043852
B10: Other (income) expense, net | C10: =C30/C25 -> -0.026138494 | D10: =D30/D25 -> -0.030873104 | E10: =E30/E25 -> -0.021906601 | F10: =F30/F25 -> -0.018866994 | G10: =G30/G25 -> -0.01840332
B11: EBIT Margin | C11: =C31/C25 -> 0.25450257 | D11: =D31/D25 -> 0.2442643 | E11: =E31/E25 -> 0.2669699 | F11: =F31/F25 -> 0.24917585 | G11: =G31/G25 -> 0.22897518
B12: Non-service related postretirement costs
B13: Interest expense, net | C13: =C32/C25 -> 0 | D13: =D32/D25 -> -0.0018724323 | E13: =E32/E25 -> -0.0019408392 | F13: =F32/F25 -> -0.0016441825 | G13: =G32/G25 -> 0.0019350399
B15: Income before income taxes (EBT Margin) | C15: =C34/C25 -> 0.25450257 | D15: =D34/D25 -> 0.24613673 | E15: =E34/E25 -> 0.26891074 | F15: =F34/F25 -> 0.25082004 | G15: =G34/G25 -> 0.22704014
B16: Provision for income taxes | C16: =C35/C25 -> 0.06811007 | D16: =D35/D25 -> 0.059124803 | E16: =E35/E25 -> 0.071711522 | F16: =F35/F25 -> 0.065471346 | G16: =G35/G25 -> 0.06277978
B17: Net income margin including noncontrolling interests | C17: =C36/C25 -> 0.1863925 | D17: =D36/D25 -> 0.18701193 | E17: =E36/E25 -> 0.19719922 | F17: =F36/F25 -> 0.18534869 | G17: =G36/G25 -> 0.16426036
B18: Less: Net income attributable to noncontrolling interests (% of Net Income) | C18: 0 | D18: 0 | E18: 0 | F18: 0 | G18: 0
B19: Net income margin | C19: =C38/C25 -> 0.1863925 | D19: =D38/D25 -> 0.18701193 | E19: =E38/E25 -> 0.19719922 | F19: =F38/F25 -> 0.18534869 | G19: =G38/G25 -> 0.16426036
B21: Effective Tax Rates (Taxes/EBIT)
B23: Horizontal Analysis
B24: ='P&L'!$B$5 -> Particulars | D24: =D4 -> FY 20 | E24: =E4 -> FY 21 | F24: =F4 -> FY 22 | G24: =G4 -> FY 23
B25: Net sales | C25: 82675 | D25: 90791 | E25: 100472 | F25: 121641 | G25: 146767
B26: Cost of sales | C26: 53867 | D26: 60732 | E26: 65413 | F26: 81998 | G26: 102353
B27: Gross profit | C27: =C25-C26 -> 28808 | D27: =D25-D26 -> 30059 | E27: =E25-E26 -> 35059 | F27: =F25-F26 -> 39643 | G27: =G25-G26 -> 44414
B29: Selling, general and administrative expenses | C29: 9928 | D29: 10685 | E29: 10437 | F29: 11628 | G29: 13509
B30: Other (income) expense, net | C30: -2161 | D30: -2803 | E30: -2201 | F30: -2295 | G30: -2701
B31: EBIT | C31: =C27-C29-C30 -> 21041 | D31: =D27-D29-D30 -> 22177 | E31: =E27-E29-E30 -> 26823 | F31: =F27-F29-F30 -> 30310 | G31: =G27-G29-G30 -> 33606
B32: Interest expense, net | C32: 0 | D32: -170 | E32: -195 | F32: -200 | G32: 284
B34: EBT | C34: =C31-C32 -> 21041 | D34: =D31-D32 -> 22347 | E34: =E31-E32 -> 27018 | F34: =F31-F32 -> 30510 | G34: =G31-G32 -> 33322
B35: Provision for income taxes | C35: 5631 | D35: 5368 | E35: 7205 | F35: 7964 | G35: 9214
B36: Net income including noncontrolling interests | C36: =C34-C35 -> 15410 | D36: =D34-D35 -> 16979 | E36: =E34-E35 -> 19813 | F36: =F34-F35 -> 22546 | G36: =G34-G35 -> 24108
B37: Less: Net income attributable to noncontrolling interests
B38: Net income | C38: =C36 -> 15410 | D38: =D36 -> 16979 | E38: =E36 -> 19813 | F38: =F36 -> 22546 | G38: =G36 -> 24108
B41: Trend Analysis | C41: ='P&L'!C5 -> FY 19 | D41: ='P&L'!D5 -> FY 20 | E41: ='P&L'!E5 -> FY 21 | F41: ='P&L'!F5 -> FY 22 | G41: ='P&L'!G5 -> FY 23
B42: Sales (in Rs.) | C42: 0 | D42: =(D25-C25)/C25 -> 0.098167523 | E42: =(E25-D25)/D25 -> 0.10662951 | F42: =(F25-E25)/E25 -> 0.21069552 | G42: =(G25-F25)/F25 -> 0.20655864
B43: Operating Profit EBIT (in Rs.) | C43: 0 | D43: =(D31-C31)/C31 -> 0.053989829 | E43: =(E31-D31)/D31 -> 0.20949633 | F43: =(F31-E31)/E31 -> 0.13000037 | G43: =(G31-F31)/F31 -> 0.10874299
B44: EBT (in Rs.) | C44: 0 | D44: =(D34-C34)/C34 -> 0.062069293 | E44: =(E34-D34)/D34 -> 0.20902135 | F44: =(F34-E34)/E34 -> 0.12924717 | G44: =(G34-F34)/F34 -> 0.092166503
B45: Net Profit (in Rs.) | C45: 0 | D45: =(D38-C38)/C38 -> 0.101817 | E45: =(E38-D38)/D38 -> 0.16691207 | F45: =(F38-E38)/E38 -> 0.13793974 | G45: =(G38-F38)/F38 -> 0.069280582
C47: =C41 -> FY 19 | D47: =D41 -> FY 20 | E47: =E41 -> FY 21 | F47: =F41 -> FY 22 | G47: =G41 -> FY 23
B48: Sales (in Trend %) | C48: 0 | D48: =D42 -> 0.098167523 | E48: =E42 -> 0.10662951 | F48: =F42 -> 0.21069552 | G48: =G42 -> 0.20655864
B49: Net Profit (in Trend %) | C49: 0 | D49: =D45 -> 0.101817 | E49: =E45 -> 0.16691207 | F49: =F45 -> 0.13793974 | G49: =G45 -> 0.069280582
B52: Growth | D52: =D47 -> FY 20 | E52: =E47 -> FY 21 | F52: =F47 -> FY 22 | G52: =G47 -> FY 23
B53: Sales (% growth) | D53: =D48 -> 0.098167523 | E53: =E48 -> 0.10662951 | F53: =F48 -> 0.21069552 | G53: =G48 -> 0.20655864
...

Sheet Funding plan
A1: ='P&L'!A1 -> 0
C4: (Rs. Crores)
B5: Particulars | C5: FY 24
B6: Capital expenditure requirements | C6: =50*100 -> 5000
B7: Less- Cash generated from operating activities | C7: 2500
B8: Funding to be raised | C8: =C6-C7 -> 2500
C13: (Rs. Crores)
B14: Particulars | C14: Amount
B15: Debt | C15: =C8*0.1667 -> 416.75
B16: Equity | C16: =C8*0.8333 -> 2083.25
B17: Total financing | C17: =SUM(C15:C16) -> 2500
